<?xml version="1.0" encoding="utf-8"?>
<!--
This URDF was automatically created by SolidWorks to URDF Exporter! Originally created by Stephen Brawner (brawner@gmail.com)
Commit Version: 1.6.0-4-g7f85cfe  Build Version: 1.6.7995.38578
For more information, please see http://wiki.ros.org/sw_urdf_exporter
-->
<robot name="hi_cl_23_240925">
	<mujoco>
		<compiler meshdir="meshes/" balanceinertia="true" discardvisual="false" />
	</mujoco>
	<link name="base_link">
		<inertial>
			<origin xyz="-0.00154853 -7.263E-05 -0.0269642" rpy="0 0 0" />
			<mass value="4" />
			<inertia ixx="0.00957622" ixy="1.02E-06" ixz="-8.442E-05" iyy="0.00654424" iyz="1.11E-06" izz="0.00526567" />
		</inertial>
		<visual>
			<origin xyz="0 0 0" rpy="0 0 0" />
			<geometry>
				<mesh filename="meshes/base_link.STL" />
			</geometry>
			<material name="">
				<color rgba="0.79216 0.81961 0.93333 1" />
			</material>
		</visual>
		<collision>
			<origin xyz="0 0 -0.07" rpy="0 0 0" />
			<geometry>
				<box size="0.14 0.20 0.25" />
				<!-- <mesh filename="meshes/base_link.STL" /> -->
			</geometry>
		</collision>
	</link>
<!-- right arm -->
	<link name="r_shoulder_pitch_link">
		<inertial>
			<origin xyz="0.00242196 -0.058252 -8.6807E-05" rpy="0 0 0" />
			<mass value="0.35" />
			<inertia ixx="0.00017393" ixy="-1.346E-05" ixz="-1.1E-07" iyy="0.00013651" iyz="-8E-07" izz="0.00020583" />
		</inertial>
		<visual>
			<origin xyz="0 0 0" rpy="0 0 0" />
			<geometry>
				<mesh filename="meshes/r_shoulder_pitch_link.STL" />
			</geometry>
			<material name="">
				<color rgba="0.89804 0.91765 0.92941 1" />
			</material>
		</visual>
		<collision>
			<origin xyz="0.00242196 -0.068252 -8.6807E-05" rpy="0 0 0" />
			<geometry>
				<box size="0.05 0.05 0.05" />
			</geometry>
		</collision>
	</link>
	<joint name="r_shoulder_pitch_joint" type="revolute">
		<origin xyz="0 -0.08085 0" rpy="0 0 0" />
		<parent link="base_link" />
		<child link="r_shoulder_pitch_link" />
		<axis xyz="0 1 0" />
		<limit lower="-3.14" upper="3.14" effort="16" velocity="21" />
	</joint>
	<link name="r_shoulder_roll_link">
		<inertial>
			<origin xyz="-0.0088047 -8.8789E-05 -0.052824" rpy="0 0 0" />
			<mass value="0.35" />
			<inertia ixx="0.00028497" ixy="-4.1E-07" ixz="8.018E-05" iyy="0.00032147" iyz="-3.6E-07" izz="0.00014121" />
		</inertial>
		<visual>
			<origin xyz="0 0 0" rpy="0 0 0" />
			<geometry>
				<mesh filename="meshes/r_shoulder_roll_link.STL" />
			</geometry>
			<material name="">
				<color rgba="0.89804 0.91765 0.92941 1" />
			</material>
		</visual>
		<collision>
			<origin xyz="-0.009 0.0 -0.052" rpy="0 0 0" />
			<geometry>
				<box size="0.04 0.04 0.04" />
			</geometry>
		</collision>
	</link>
	<joint name="r_shoulder_roll_joint" type="revolute">
		<origin xyz="0 -0.06515 0" rpy="0 0 0" />
		<parent link="r_shoulder_pitch_link" />
		<child link="r_shoulder_roll_link" />
		<axis xyz="1 0 0" />
		<limit lower="-3.14" upper="0.45" effort="16" velocity="21" />
	</joint>
	<link name="r_arm_yaw_link">
		<inertial>
			<origin xyz="-0.002422 -8.6807E-05 -0.059552" rpy="0 0 0" />
			<mass value="0.35" />
			<inertia ixx="0.00017393" ixy="1.1E-07" ixz="1.346E-05" iyy="0.00020583" iyz="-8E-07" izz="0.00013651" />
		</inertial>
		<visual>
			<origin xyz="0 0 0" rpy="0 0 0" />
			<geometry>
				<mesh filename="meshes/r_arm_yaw_link.STL" />
			</geometry>
			<material name="">
				<color rgba="0.89804 0.91765 0.92941 1" />
			</material>
		</visual>
	</link>
	<joint name="r_arm_yaw_joint" type="revolute">
		<origin xyz="-0.0026 0 -0.06495" rpy="0 0 -1.5707963" />
		<parent link="r_shoulder_roll_link" />
		<child link="r_arm_yaw_link" />
		<axis xyz="0 0 1" />
		<limit lower="-3.14" upper="3.14" effort="16" velocity="21" />
	</joint>
	<link name="r_arm_roll_link">
		<inertial>
			<origin xyz="0.0088047 8.8789E-05 -0.052824" rpy="0 0 0" />
			<mass value="0.35" />
			<inertia ixx="0.00028497" ixy="-4.1E-07" ixz="-8.018E-05" iyy="0.00032147" iyz="3.6E-07" izz="0.00014121" />
		</inertial>
		<visual>
			<origin xyz="0 0 0" rpy="0 0 0" />
			<geometry>
				<mesh filename="meshes/r_arm_roll_link.STL" />
			</geometry>
			<material name="">
				<color rgba="0.89804 0.91765 0.92941 1" />
			</material>
		</visual>
		<collision>
			<origin xyz="0.0088047 8.8789E-05 -0.032824" rpy="0 0 0" />
			<geometry>
				<box size="0.03 0.03 0.14" />
			</geometry>
		</collision>
	</link>
	<joint name="r_arm_roll_joint" type="revolute">
		<origin xyz="0 0 -0.06645" rpy="1.5707963 0 0" />
		<parent link="r_arm_yaw_link" />
		<child link="r_arm_roll_link" />
		<axis xyz="1 0 0" />
		<limit lower="-3.14" upper="0.4" effort="16" velocity="21" />
	</joint>
	<link name="r_wrist_yaw_link">
		<inertial>
			<origin xyz="0 0 -0.06558" rpy="0 0 0" />
			<mass value="0.035143" />
			<inertia ixx="1.2175E-05" ixy="9.4252E-23" ixz="1.2115E-20" iyy="1.2175E-05" iyz="-1.456E-19" izz="3.7315E-06" />
		</inertial>
		<visual>
			<origin xyz="0 0 0" rpy="0 0 0" />
			<geometry>
				<mesh filename="meshes/r_wrist_yaw_link.STL" />
			</geometry>
			<material name="">
				<color rgba="0.49804 0.49804 0.49804 1" />
			</material>
		</visual>
		<collision>
			<origin xyz="0 0 -0.07558" rpy="0 0 0" />
			<geometry>
 				<sphere radius="0.02"/>
			</geometry>
		</collision>
	</link>
	<joint name="r_wrist_yaw_joint" type="fixed">
		<origin xyz="0.0026 0 -0.06495" rpy="0 0 0" />
		<parent link="r_arm_roll_link" />
		<child link="r_wrist_yaw_link" />
		<axis xyz="0 0 1" />
		<limit lower="-3.14" upper="3.14" effort="16" velocity="21" />
	</joint>
<!-- left arm -->
	<link name="l_shoulder_pitch_link">
		<inertial>
			<origin xyz="0.00095302 0.058734 -8.0741E-05" rpy="0 0 0" />
			<mass value="0.35" />
			<inertia ixx="0.00016981" ixy="1.582E-05" ixz="-6E-08" iyy="0.00014053" iyz="7.3E-07" izz="0.00020608" />
		</inertial>
		<visual>
			<origin xyz="0 0 0" rpy="0 0 0" />
			<geometry>
				<mesh filename="meshes/l_shoulder_pitch_link.STL" />
			</geometry>
			<material name="">
				<color rgba="1 1 1 1" />
			</material>
		</visual>
		<collision>
			<origin xyz="0.00095302 0.068734 -8.0741E-05" rpy="0 0 0" />
			<geometry>
				<box size="0.05 0.05 0.05" />
			</geometry>
		</collision>
	</link>
	<joint name="l_shoulder_pitch_joint" type="revolute">
		<origin xyz="0 0.08085 0" rpy="0 0 0" />
		<parent link="base_link" />
		<child link="l_shoulder_pitch_link" />
		<axis xyz="0 1 0" />
		<limit lower="-3.14" upper="3.14" effort="16" velocity="21" />
	</joint>
	<link name="l_shoulder_roll_link">
		<inertial>
			<origin xyz="-0.0088047 8.879E-05 -0.052824" rpy="0 0 0" />
			<mass value="0.35" />
			<inertia ixx="0.00028497" ixy="4.1E-07" ixz="8.018E-05" iyy="0.00032147" iyz="3.6E-07" izz="0.00014121" />
		</inertial>
		<visual>
			<origin xyz="0 0 0" rpy="0 0 0" />
			<geometry>
				<mesh filename="meshes/l_shoulder_roll_link.STL" />
			</geometry>
			<material name="">
				<color rgba="0.89804 0.91765 0.92941 1" />
			</material>
		</visual>
		<collision>
			<origin xyz="-0.009 0.0 -0.052" rpy="0 0 0" />
			<geometry>
				<box size="0.04 0.04 0.04" />
			</geometry>
		</collision>
	</link>
	<joint name="l_shoulder_roll_joint" type="revolute">
		<origin xyz="0 0.06515 0" rpy="0 0 0" />
		<parent link="l_shoulder_pitch_link" />
		<child link="l_shoulder_roll_link" />
		<axis xyz="1 0 0" />
		<limit lower="-0.45" upper="3.14" effort="16" velocity="21" />
	</joint>
	<link name="l_arm_yaw_link">
		<inertial>
			<origin xyz="-0.002422 8.6807E-05 -0.059552" rpy="0 0 0" />
			<mass value="0.35" />
			<inertia ixx="0.00017393" ixy="-1.1E-07" ixz="1.346E-05" iyy="0.00020583" iyz="8E-07" izz="0.00013651" />
		</inertial>
		<visual>
			<origin xyz="0 0 0" rpy="0 0 0" />
			<geometry>
				<mesh filename="meshes/l_arm_yaw_link.STL" />
			</geometry>
			<material name="">
				<color rgba="0.89804 0.91765 0.92941 1" />
			</material>
		</visual>
	</link>
	<joint name="l_arm_yaw_joint" type="revolute">
		<origin xyz="-0.0026 0 -0.06495" rpy="0 0 1.5707963" />
		<parent link="l_shoulder_roll_link" />
		<child link="l_arm_yaw_link" />
		<axis xyz="0 0 1" />
		<limit lower="-3.14" upper="3.14" effort="16" velocity="21" />
	</joint>
	<link name="l_arm_roll_link">
		<inertial>
			<origin xyz="0.0088047 -8.879E-05 -0.052824" rpy="0 0 0" />
			<mass value="0.35" />
			<inertia ixx="0.00028497" ixy="4.1E-07" ixz="-8.018E-05" iyy="0.00032147" iyz="-3.6E-07" izz="0.00014121" />
		</inertial>
		<visual>
			<origin xyz="0 0 0" rpy="0 0 0" />
			<geometry>
				<mesh filename="meshes/l_arm_roll_link.STL" />
			</geometry>
			<material name="">
				<color rgba="0.89804 0.91765 0.92941 1" />
			</material>
		</visual>
		<collision>
			<origin xyz="0.0088047 -8.879E-05 -0.032824" rpy="0 0 0" />
			<geometry>
				<box size="0.03 0.03 0.14" />
			</geometry>
		</collision>
	</link>
	<joint name="l_arm_roll_joint" type="revolute">
		<origin xyz="0 0 -0.06645" rpy="-1.5707963 0 0" />
		<parent link="l_arm_yaw_link" />
		<child link="l_arm_roll_link" />
		<axis xyz="1 0 0" />
		<limit lower="-0.4" upper="3.14" effort="16" velocity="21" />
	</joint>
	<link name="l_wrist_yaw_link">
		<inertial>
			<origin xyz="1.1102E-16 3.7151E-14 -0.06558" rpy="0 0 0" />
			<mass value="0.035143" />
			<inertia ixx="1.2175E-05" ixy="2.3882E-22" ixz="2.2238E-20" iyy="1.2175E-05" iyz="3.9298E-20" izz="3.7315E-06" />
		</inertial>
		<visual>
			<origin xyz="0 0 0" rpy="0 0 0" />
			<geometry>
				<mesh filename="meshes/l_wrist_yaw_link.STL" />
			</geometry>
			<material name="">
				<color rgba="0.49804 0.49804 0.49804 1" />
			</material>
		</visual>
		<collision>
			<origin xyz="0.0 0.0 -0.07558" rpy="0 0 0" />
			<geometry>
 				<sphere radius="0.02"/>
			</geometry>
		</collision>
	</link>
	<joint name="l_wrist_yaw_joint" type="fixed">
		<origin xyz="0.0026 0 -0.06495" rpy="0 0 0" />
		<parent link="l_arm_roll_link" />
		<child link="l_wrist_yaw_link" />
		<axis xyz="0 0 1" />
		<limit lower="-3.14" upper="3.14" effort="16" velocity="21" />
	</joint>
<!-- loin -->
	<link name="loin_yaw_link">
		<inertial>
			<origin xyz="0 0 -0.060242" rpy="0 0 0" />
			<mass value="1.305" />
			<inertia ixx="0.0015765" ixy="2.98E-06" ixz="0" iyy="0.00041876" iyz="0" izz="0.0014561" />
		</inertial>
		<visual>
			<origin xyz="0 0 0" rpy="0 0 0" />
			<geometry>
				<mesh filename="meshes/loin_yaw_link.STL" />
			</geometry>
			<material name="">
				<color rgba="1 1 1 1" />
			</material>
		</visual>
		<collision>
			<origin xyz="0 0 -0.06" rpy="0 0 0" />
			<geometry>
				<box size="0.06 0.12 0.06" />
				<!-- <mesh filename="meshes/loin_yaw_link.STL" /> -->
			</geometry>
		</collision>
	</link>
	<joint name="torso_joint" type="revolute">
		<origin xyz="0 0 0.19425" rpy="0 0 0" />
		<parent link="loin_yaw_link" />
		<child link="base_link" />
		<axis xyz="0 0 1" />
		<limit lower="-3.14" upper="3.14" effort="36" velocity="21" />
	</joint>
<!-- right leg -->
	<link name="r_hip_pitch_link">
		<inertial>
			<origin xyz="-0.00022626 -0.06684 9.015E-05" rpy="0 0 0" />
			<mass value="0.661" />
			<inertia ixx="0.00018617" ixy="-1E-08" ixz="1.2E-07" iyy="0.00019782" iyz="4.7E-07" izz="0.0002263" />
		</inertial>
		<visual>
			<origin xyz="0 0 0" rpy="0 0 0" />
			<geometry>
				<mesh filename="meshes/r_hip_pitch_link.STL" />
			</geometry>
			<material name="">
				<color rgba="0.79216 0.81961 0.93333 1" />
			</material>
		</visual>
		<collision>
			<origin xyz="0 -0.07 0" rpy="0 0 0" />
			<geometry>
				<box size="0.06 0.06 0.06" />
				<!-- <mesh filename="meshes/r_hip_pitch_link.STL" /> -->
			</geometry>
		</collision>
	</link>
	<joint name="r_hip_pitch_joint" type="revolute">
		<origin xyz="0 -0.02875 -0.06425" rpy="0 -0.4 0" />
		<parent link="loin_yaw_link" />
		<child link="r_hip_pitch_link" />
		<axis xyz="0 1 0" />
		<limit lower="-1.0" upper="1.8" effort="36" velocity="21" />
	</joint>
	<link name="r_hip_roll_link">
		<inertial>
			<origin xyz="0.00088845 -0.00019059 -0.066357" rpy="0 0 0" />
			<mass value="0.54219" />
			<inertia ixx="0.00096893" ixy="-6.4E-07" ixz="-2.26E-05" iyy="0.0012165" iyz="-2.89E-06" izz="0.0004037" />
		</inertial>
		<visual>
			<origin xyz="0 0 0" rpy="0 0 0" />
			<geometry>
				<mesh filename="meshes/r_hip_roll_link.STL" />
			</geometry>
			<material name="">
				<color rgba="0.89804 0.91765 0.92941 1" />
			</material>
		</visual>
		<collision>
			<origin xyz="0 0 -0.08" rpy="0 0 0" />
			<geometry>
				<box size="0.06 0.06 0.06" />
				<!-- <mesh filename="meshes/r_hip_roll_link.STL" /> -->
			</geometry>
		</collision>
	</link>
	<joint name="r_hip_roll_joint" type="revolute">
		<origin xyz="0 -0.06875 0" rpy="0 0 0" />
		<parent link="r_hip_pitch_link" />
		<child link="r_hip_roll_link" />
		<axis xyz="1 0 0" />
		<limit lower="-0.5" upper="0.12" effort="36" velocity="21" />
	</joint>
	<link name="r_thigh_link">
		<inertial>
			<origin xyz="0 0.0019897 -0.066297" rpy="0 0 0" />
			<mass value="0.23898" />
			<inertia ixx="0.00050536" ixy="-1.1811E-12" ixz="5.2665E-11" iyy="0.00032488" iyz="1.858E-05" izz="0.00029126" />
		</inertial>
		<visual>
			<origin xyz="0 0 0" rpy="0 0 0" />
			<geometry>
				<mesh filename="meshes/r_thigh_link.STL" />
			</geometry>
			<material name="">
				<color rgba="0.89804 0.91765 0.92941 1" />
			</material>
		</visual>
		<collision>
			<origin xyz="0 0 -0.06" rpy="0 0 0" />
			<geometry>
				<box size="0.06 0.06 0.06" />
				<mesh filename="meshes/r_thigh_link.STL" />
			</geometry>
		</collision>
	</link>
	<joint name="r_hip_yaw_joint" type="revolute">
		<origin xyz="0 0 -0.09425" rpy="0 0 0" />
		<parent link="r_hip_roll_link" />
		<child link="r_thigh_link" />
		<axis xyz="0 0 1" />
		<limit lower="-0.6" upper="0.3" effort="36" velocity="21" />
	</joint>
	<link name="r_calf_link">
		<inertial>
			<origin xyz="-8.965E-05 -0.0020679 -0.050651" rpy="0 0 0" />
			<mass value="1.2" />
			<inertia ixx="0.0068013" ixy="2.6E-07" ixz="-3.47E-06" iyy="0.006751" iyz="-4.2E-07" izz="0.00034715" />
		</inertial>
		<visual>
			<origin xyz="0 0 0" rpy="0 0 0" />
			<geometry>
				<mesh filename="meshes/r_calf_link.STL" />
			</geometry>
			<material name="">
				<color rgba="0.79216 0.81961 0.93333 1" />
			</material>
		</visual>
		<collision>
			<origin xyz="0 0 -0.1" rpy="0 0 0" />
			<geometry>
				<box size="0.012 0.06 0.1" />
				<!-- <mesh filename="meshes/r_calf_link.STL" /> -->
			</geometry>
		</collision>
	</link>
	<joint name="r_knee_joint" type="revolute">
		<origin xyz="0 0 -0.10575" rpy="0 0.8 0" />
		<parent link="r_thigh_link" />
		<child link="r_calf_link" />
		<axis xyz="0 1 0" />
		<limit lower="-0.8" upper="1.5" effort="36" velocity="21" />
	</joint>
	<link name="r_ankle_pitch_link">
		<inertial>
			<origin xyz="0.0072806 0.00051939 2.2469E-12" rpy="0 0 0" />
			<mass value="0.16682" />
			<inertia ixx="0.0001187" ixy="1E-06" ixz="0" iyy="0.0001994" iyz="3.7295E-17" izz="0.00028526" />
		</inertial>
		<visual>
			<origin xyz="0 0 0" rpy="0 0 0" />
			<geometry>
				<mesh filename="meshes/r_ankle_pitch_link.STL" />
			</geometry>
			<material name="">
				<color rgba="0.89804 0.91765 0.92941 1" />
			</material>
		</visual>
		<collision>
			<origin xyz="0 0 0" rpy="0 0 0" />
			<geometry>
				<box size="0.078 0.08 0.05" />
				<!-- <mesh filename="meshes/r_ankle_pitch_link.STL" /> -->
			</geometry>
		</collision>
	</link>
	<joint name="r_ankle_pitch_joint" type="revolute">
		<origin xyz="0 0 -0.2" rpy="0 -0.4 0" />
		<parent link="r_calf_link" />
		<child link="r_ankle_pitch_link" />
		<axis xyz="0 1 0" />
		<limit lower="-0.45" upper="1.15" effort="16" velocity="21" />
	</joint>
	<link name="r_ankle_roll_link">
		<inertial>
			<origin xyz="-0.040001 9.312E-05 -0.023563" rpy="0 0 0" />
			<mass value="0.5" />
			<inertia ixx="0.00040772" ixy="-2.34E-06" ixz="-9.125E-05" iyy="0.0015071" iyz="-4.6E-07" izz="0.0013858" />
		</inertial>
		<visual>
			<origin xyz="0 0 0" rpy="0 0 0" />
			<geometry>
				<mesh filename="meshes/r_ankle_roll_link.STL" />
			</geometry>
			<material name="">
				<color rgba="1 1 1 1" />
			</material>
		</visual>
		<collision>
			<origin xyz="0 0 0" rpy="0 0 0" />
			<geometry>
				<mesh filename="meshes/r_ankle_roll_link.STL" />
			</geometry>
		</collision>
	</link>
	<joint name="r_ankle_roll_joint" type="revolute">
		<origin xyz="0.07525 -0.0003 0" rpy="0 0 0" />
		<parent link="r_ankle_pitch_link" />
		<child link="r_ankle_roll_link" />
		<axis xyz="1 0 0" />
		<limit lower="-0.15" upper="0.15" effort="16" velocity="21" />
	</joint>
<!-- left leg -->
	<link name="l_hip_pitch_link">
		<inertial>
			<origin xyz="-0.00022626 0.06700617 8.992E-05" rpy="0 0 0" />
			<mass value="0.661" />
			<inertia ixx="0.00018657" ixy="1.9E-07" ixz="1.1E-07" iyy="0.00019782" iyz="2.5E-07" izz="0.00022671" />
		</inertial>
		<visual>
			<origin xyz="0 0 0" rpy="0 0 0" />
			<geometry>
				<mesh filename="meshes/l_hip_pitch_link.STL" />
			</geometry>
			<material name="">
				<color rgba="0.79216 0.81961 0.93333 1" />
			</material>
		</visual>
		<collision>
			<origin xyz="0 0.07 0" rpy="0 0 0" />
			<geometry>
				<box size="0.06 0.06 0.06" />
				<!-- <mesh filename="meshes/l_hip_pitch_link.STL" /> -->
			</geometry>
		</collision>
	</link>
	<joint name="l_hip_pitch_joint" type="revolute">
		<origin xyz="0 0.02875 -0.06425" rpy="0 -0.4 0" />
		<parent link="loin_yaw_link" />
		<child link="l_hip_pitch_link" />
		<axis xyz="0 1 0" />
		<limit lower="-1.0" upper="1.8" effort="36" velocity="21" />
	</joint>
	<link name="l_hip_roll_link">
		<inertial>
			<origin xyz="0.00051186 -0.000186 -0.06635681" rpy="0 0 0" />
			<mass value="0.54219" />
			<inertia ixx="0.00096867" ixy="4.9E-07" ixz="-2.833E-05" iyy="0.00121705" iyz="-2.83E-06" izz="0.00040399" />
		</inertial>
		<visual>
			<origin xyz="0 0 0" rpy="0 0 0" />
			<geometry>
				<mesh filename="meshes/l_hip_roll_link.STL" />
			</geometry>
			<material name="">
				<color rgba="0.89804 0.91765 0.92941 1" />
			</material>
		</visual>
		<collision>
			<origin xyz="0 0 -0.08" rpy="0 0 0" />
			<geometry>
				<box size="0.06 0.06 0.06" />
				<!-- <mesh filename="meshes/l_hip_roll_link.STL" /> -->
			</geometry>
		</collision>
	</link>
	<joint name="l_hip_roll_joint" type="revolute">
		<origin xyz="0 0.06875 0" rpy="0 0 0" />
		<parent link="l_hip_pitch_link" />
		<child link="l_hip_roll_link" />
		<axis xyz="1 0 0" />
		<limit lower="-0.12" upper="0.5" effort="36" velocity="21" />
	</joint>
	<link name="l_thigh_link">
		<inertial>
			<origin xyz="0 -0.0019897 -0.066297" rpy="0 0 0" />
			<mass value="0.23898" />
			<inertia ixx="0.00050536" ixy="0" ixz="0" iyy="0.00032488" iyz="-1.858E-05" izz="0.00029126" />
		</inertial>
		<visual>
			<origin xyz="0 0 0" rpy="0 0 0" />
			<geometry>
				<mesh filename="meshes/l_thigh_link.STL" />
			</geometry>
			<material name="">
				<color rgba="0.89804 0.91765 0.92941 1" />
			</material>
		</visual>
		<collision>
			<origin xyz="0 0 -0.06" rpy="0 0 0" />
			<geometry>
				<box size="0.06 0.06 0.06" />
				<!-- <mesh filename="meshes/l_thigh_link.STL" /> -->
			</geometry>
		</collision>
	</link>
	<joint name="l_hip_yaw_joint" type="revolute">
		<origin xyz="0 0 -0.09425" rpy="0 0 0" />
		<parent link="l_hip_roll_link" />
		<child link="l_thigh_link" />
		<axis xyz="0 0 1" />
		<limit lower="-0.3" upper="0.6" effort="36" velocity="21" />
	</joint>
	<link name="l_calf_link">
		<inertial>
			<origin xyz="8.965E-05 0.00206794 -0.05065108" rpy="0 0 0" />
			<mass value="1.2" />
			<inertia ixx="0.0068013" ixy="2.6E-07" ixz="3.47E-06" iyy="0.00675095" iyz="4.2E-07" izz="0.00034715" />
		</inertial>
		<visual>
			<origin xyz="0 0 0" rpy="0 0 0" />
			<geometry>
				<mesh filename="meshes/l_calf_link.STL" />
			</geometry>
			<material name="">
				<color rgba="1 1 1 1" />
			</material>
		</visual>
		<collision>
			<origin xyz="0 0 -0.1" rpy="0 0 0" />
			<geometry>
				<box size="0.012 0.06 0.1" />
				<!-- <mesh filename="meshes/l_calf_link.STL" /> -->
			</geometry>
		</collision>
	</link>
	<joint name="l_knee_joint" type="revolute">
		<origin xyz="0 0 -0.10575" rpy="0 0.8 0" />
		<parent link="l_thigh_link" />
		<child link="l_calf_link" />
		<axis xyz="0 1 0" />
		<limit lower="-0.8" upper="1.5" effort="36" velocity="21" />
	</joint>
	<link name="l_ankle_pitch_link">
		<inertial>
			<origin xyz="0.00467932 -0.00047699 2.1252E-12" rpy="0 0 0" />
			<mass value="0.16682" />
			<inertia ixx="0.00011981" ixy="-6.4E-07" ixz="-8.1927E-13" iyy="0.00022179" iyz="-3.7346E-17" izz="0.00030766" />
		</inertial>
		<visual>
			<origin xyz="0 0 0" rpy="0 0 0" />
			<geometry>
				<mesh filename="meshes/l_ankle_pitch_link.STL" />
			</geometry>
			<material name="">
				<color rgba="0.89804 0.91765 0.92941 1" />
			</material>
		</visual>
		<collision>
			<origin xyz="0 0 0" rpy="0 0 0" />
			<geometry>
				<box size="0.078 0.08 0.05" />
				<!-- <mesh filename="meshes/l_ankle_pitch_link.STL" /> -->
			</geometry>
		</collision>
	</link>
	<joint name="l_ankle_pitch_joint" type="revolute">
		<origin xyz="0 0 -0.2" rpy="0 -0.4 0" />
		<parent link="l_calf_link" />
		<child link="l_ankle_pitch_link" />
		<axis xyz="0 1 0" />
		<limit lower="-0.45" upper="1.15" effort="16" velocity="21" />
	</joint>
	<link name="l_ankle_roll_link">
		<inertial>
			<origin xyz="-0.03772 9.584E-05 -0.02425" rpy="0 0 0" />
			<mass value="0.5" />
			<inertia ixx="0.0004095" ixy="-2.3E-06" ixz="-0.00012156" iyy="0.00145" iyz="-5.1E-07" izz="0.0013334" />
		</inertial>
		<visual>
			<origin xyz="0 0 0" rpy="0 0 0" />
			<geometry>
				<mesh filename="meshes/l_ankle_roll_link.STL" />
			</geometry>
			<material name="">
				<color rgba="0.89804 0.91765 0.92941 1" />
			</material>
		</visual>
		<collision>
			<origin xyz="0 0 0" rpy="0 0 0" />
			<geometry>
				<mesh filename="meshes/l_ankle_roll_link.STL" />
			</geometry>
		</collision>
	</link>
	<joint name="l_ankle_roll_joint" type="revolute">
		<origin xyz="0.07525 0.0003 0" rpy="0 0 0" />
		<parent link="l_ankle_pitch_link" />
		<child link="l_ankle_roll_link" />
		<axis xyz="1 0 0" />
		<limit lower="-0.15" upper="0.15" effort="16" velocity="21" />
	</joint>
	<link name="l_toe_link"/>
	<joint name="l_toe_joint" type="fixed">
		<origin xyz="-0.0 0.02 -0.03" rpy="0 0 0" />
		<parent link="l_ankle_roll_link" />
		<child link="l_toe_link" />
	</joint>
	<link name="r_toe_link"/>
	<joint name="r_toe_joint" type="fixed">
		<origin xyz="-0.0 -0.02 -0.03" rpy="0 0 0" />
		<parent link="r_ankle_roll_link" />
		<child link="r_toe_link" />
	</joint>
	<link name="l_hand_link"/>
	<joint name="l_hand_joint" type="fixed">
		<origin xyz="0.0 0 -0.07" rpy="0 0 0" />
		<parent link="l_wrist_yaw_link" />
		<child link="l_hand_link" />
	</joint>
	<link name="r_hand_link"/>
	<joint name="r_hand_joint" type="fixed">
		<origin xyz="0.0 0 -0.07" rpy="0 0 0" />
		<parent link="r_wrist_yaw_link" />
		<child link="r_hand_link" />
	</joint>
	<link name="head_link"/>
	<joint name="head_joint" type="fixed">
		<origin xyz="0.0 0 0.12" rpy="0 0 0" />
		<parent link="base_link" />
		<child link="head_link" />
	</joint>
</robot>
