<mujoco model="hi_23dof">
    <compiler angle="radian" meshdir="meshes" eulerseq="zyx"/>
    <option timestep='0.002' iterations='50' solver='Newton' gravity='0 0 -9.81' integrator='RK4'/>
    <size njmax="500" nconmax="100" />
    <visual>
        <quality shadowsize='4096'/>
        <map znear='0.05'/>
    </visual>
    <visual>
        <global offwidth="640" offheight="640"/>
    </visual>
    <default>
        <joint limited='true'/>
        <motor ctrllimited='true'/>
        <geom  condim='4' contype="1" conaffinity="15" solref='0.001 2' friction='0.9 0.2 0.2'/>
        <equality solref='0.001 2'/>
        <default class='visualgeom'>
            <geom material='visualgeom' condim='1' contype='0' conaffinity='0'/>
        </default>
        <default class='visualgeom2'>
            <geom material='visualgeom2' condim='1' contype='0' conaffinity='0'/>
        </default>
        <default class='obstacle'>
            <geom material='obstacle' condim='3' contype='1' conaffinity='15'/>
        </default>
    </default>
    <asset>
        <texture type="skybox" builtin="gradient" rgb1="0.3 0.5 0.7" rgb2="0 0 0" width="512" height="512"/>
        <texture name="texplane" type="2d" builtin="checker" rgb1=".2 .3 .4" rgb2=".1 0.15 0.2"
          width="512" height="512" mark="cross" markrgb=".8 .8 .8"/>
        <texture name="texplane2" type="2d" builtin="checker" rgb1="1 0.3137 0.1843" rgb2="0.0 0.30196 0.38039"
          width="512" height="512" mark="cross" markrgb=".8 .8 .8"/>
        <material name="matplane" reflectance="0." texture="texplane" texrepeat="1 1" texuniform="true"/>
        <material name="matplane2" reflectance="0.1" texture="texplane2" texrepeat="1 1" texuniform="true"/>
        <material name='obstacle'  rgba='0.9 0.6 0.2 1'/>
        <material name='visualgeom'  rgba='0.5 0.9 0.2 1'/>
        <material name='visualgeom2'  rgba='0.5 0.9 0.2 1'/>
        <mesh name="base_link" file="base_link.STL" />
        <mesh name="r_shoulder_pitch_link" file="r_shoulder_pitch_link.STL" />
        <mesh name="r_shoulder_roll_link" file="r_shoulder_roll_link.STL" />
        <mesh name="r_arm_yaw_link" file="r_arm_yaw_link.STL" />
        <mesh name="r_arm_roll_link" file="r_arm_roll_link.STL" />
        <mesh name="r_wrist_yaw_link" file="r_wrist_yaw_link.STL" />
        <mesh name="l_shoulder_pitch_link" file="l_shoulder_pitch_link.STL" />
        <mesh name="l_shoulder_roll_link" file="l_shoulder_roll_link.STL" />
        <mesh name="l_arm_yaw_link" file="l_arm_yaw_link.STL" />
        <mesh name="l_arm_roll_link" file="l_arm_roll_link.STL" />
        <mesh name="l_wrist_yaw_link" file="l_wrist_yaw_link.STL" />
        <mesh name="loin_yaw_link" file="loin_yaw_link.STL" />
        <mesh name="r_hip_pitch_link" file="r_hip_pitch_link.STL" />
        <mesh name="r_hip_roll_link" file="r_hip_roll_link.STL" />
        <mesh name="r_thigh_link" file="r_thigh_link.STL" />
        <mesh name="r_calf_link" file="r_calf_link.STL" />
        <mesh name="r_ankle_pitch_link" file="r_ankle_pitch_link.STL" />
        <mesh name="r_ankle_roll_link" file="r_ankle_roll_link.STL" />
        <mesh name="l_hip_pitch_link" file="l_hip_pitch_link.STL" />
        <mesh name="l_hip_roll_link" file="l_hip_roll_link.STL" />
        <mesh name="l_thigh_link" file="l_thigh_link.STL" />
        <mesh name="l_calf_link" file="l_calf_link.STL" />
        <mesh name="l_ankle_pitch_link" file="l_ankle_pitch_link.STL" />
        <mesh name="l_ankle_roll_link" file="l_ankle_roll_link.STL" />
        <hfield name='hf0' nrow='200' ncol='200' size="10 5 0.2 .1"/>
    </asset>
    <worldbody>
        <light directional="true" diffuse=".4 .4 .4" specular="0.1 0.1 0.1" pos="0 0 5.0" dir="0 0 -1" castshadow="false"/>
        <light directional="true" diffuse=".6 .6 .6" specular="0.2 0.2 0.2" pos="0 0 4" dir="0 0 -1"/>
        <geom name="ground" type="plane" size="0 0 1" pos="0.001 0 0" quat="1 0 0 0" material="matplane" condim="1" conaffinity="15" friction="1.0 0.1 0.01"/>
        <body name="loin_yaw_link" pos="0.0 0.0 0.5">
            <inertial pos="0 0 -0.060242" mass="1.305" diaginertia="0.0015765 0.00041876 0.0014561" />
            <joint type='slide' axis='1 0 0' limited='false' />
            <joint type='slide' axis='0 1 0' limited='false' />
            <joint type='slide' axis='0 0 1' limited='false' />
            <joint type='ball' limited='false' />

            <geom type="mesh" mesh="loin_yaw_link" contype="1" conaffinity="1" group="1" density="0" />
            <body name="l_hip_pitch_link" pos="0 0.02875 -0.06425">
                <inertial pos="-0.00022626 0.0670062 8.992e-05" mass="0.661" diaginertia="0.00018657 0.00019782 0.00022671" />
                <joint name="l_hip_pitch_joint" pos="0 0 0" axis="0 1 0" ref="0.4" range="-1 1.8" />
                <geom type="mesh" mesh="l_hip_pitch_link" contype="1" conaffinity="1" group="1" density="0" />
                <body name="l_hip_roll_link" pos="0 0.06875 0">
                    <inertial pos="0.00051186 -0.000186 -0.0663568" mass="0.54219" diaginertia="0.00096867 0.00121705 0.00040399" />
                    <joint name="l_hip_roll_joint" pos="0 0 0" axis="1 0 0" range="0 0.001" />
                    <geom type="mesh" mesh="l_hip_roll_link" contype="1" conaffinity="1" group="1" density="0" />
                    <body name="l_thigh_link" pos="0 0 -0.09425">
                        <inertial pos="0 -0.0019897 -0.066297" mass="0.23898" diaginertia="0.00050536 0.00032488 0.00029126" />
                        <joint name="l_hip_yaw_joint" pos="0 0 0" axis="0 0 1" range="0 0.001" />
                        <geom type="mesh" mesh="l_thigh_link" contype="1" conaffinity="1" group="1" density="0" />
                        <body name="l_calf_link" pos="0 0 -0.10575">
                            <inertial pos="8.965e-05 0.00206794 -0.0506511" mass="1.2" diaginertia="0.0068013 0.00675095 0.00034715" />
                            <joint name="l_knee_joint" pos="0 0 0" axis="0 1 0" ref="-0.8" range="-0.8 1.5" />
                            <geom type="mesh" mesh="l_calf_link" contype="1" conaffinity="1" group="1" density="0" />
                            <body name="l_ankle_pitch_link" pos="0 0 -0.2">
                                <inertial pos="0.00467932 -0.00047699 2.1252e-12" mass="0.16682" diaginertia="0.00011981 0.00022179 0.00030766" />
                                <joint name="l_ankle_pitch_joint" pos="0 0 0" axis="0 1 0" ref="0.4" range="-0.45 1.15" />
                                <geom type="mesh" mesh="l_ankle_pitch_link" contype="1" conaffinity="1" group="1" density="0" />
                                <body name="l_ankle_roll_link" pos="0.07525 0.0003 0">
                                    <inertial pos="-0.03772 9.584e-05 -0.02425" mass="0.5" diaginertia="0.0004095 0.00145 0.0013334" />
                                    <joint name="l_ankle_roll_joint" pos="0 0 0" axis="1 0 0" range="-0.15 0.15" />
                                    <geom type="mesh" mesh="l_ankle_roll_link" contype="0" conaffinity="0" group="1" density="0" />
                                    <geom size="0.085 0.035 0.004" pos="-0.052 0 -0.043" type="box" rgba="1 1 1 1"/>
                                </body>
                            </body>
                        </body>
                    </body>
                </body>
            </body>
            <body name="r_hip_pitch_link" pos="0 -0.02875 -0.06425">
                <inertial pos="-0.00022626 -0.06684 9.015e-05" mass="0.661" diaginertia="0.00018617 0.00019782 0.0002263" />
                <joint name="r_hip_pitch_joint" pos="0 0 0" axis="0 1 0" ref="0.4" range="-1 1.8" />
                <geom type="mesh" mesh="r_hip_pitch_link" contype="1" conaffinity="1" group="1" density="0" />
                <body name="r_hip_roll_link" pos="0 -0.06875 0">
                    <inertial pos="0.00088845 -0.00019059 -0.066357" mass="0.54219" diaginertia="0.00096893 0.0012165 0.0004037" />
                    <joint name="r_hip_roll_joint" pos="0 0 0" axis="1 0 0" range="0 0.001" />
                    <geom type="mesh" mesh="r_hip_roll_link" contype="1" conaffinity="1" group="1" density="0" />
                    <body name="r_thigh_link" pos="0 0 -0.09425">
                        <inertial pos="0 0.0019897 -0.066297" mass="0.23898" diaginertia="0.00050536 0.00032488 0.00029126" />
                        <joint name="r_hip_yaw_joint" pos="0 0 0" axis="0 0 1" range="0 0.001" />
                        <geom type="mesh" mesh="r_thigh_link" contype="1" conaffinity="1" group="1" density="0" />
                        <body name="r_calf_link" pos="0 0 -0.10575">
                            <inertial pos="-8.965e-05 -0.0020679 -0.050651" mass="1.2" diaginertia="0.0068013 0.006751 0.00034715" />
                            <joint name="r_knee_joint" pos="0 0 0" axis="0 1 0" ref="-0.8" range="-0.8 1.5" />
                            <geom type="mesh" mesh="r_calf_link" contype="1" conaffinity="1" group="1" density="0" />
                            <body name="r_ankle_pitch_link" pos="0 0 -0.2">
                                <inertial pos="0.0072806 0.00051939 2.2469e-12" mass="0.16682" diaginertia="0.0001187 0.0001994 0.00028526" />
                                <joint name="r_ankle_pitch_joint" pos="0 0 0" axis="0 1 0" ref="0.4" range="-0.45 1.15" />
                                <geom type="mesh" mesh="r_ankle_pitch_link" contype="1" conaffinity="1" group="1" density="0" />
                                <body name="r_ankle_roll_link" pos="0.07525 -0.0003 0">
                                    <inertial pos="-0.040001 9.312e-05 -0.023563" mass="0.5" diaginertia="0.00040772 0.0015071 0.0013858" />
                                    <joint name="r_ankle_roll_joint" pos="0 0 0" axis="1 0 0" range="-0.15 0.15" />
                                    <geom type="mesh" mesh="r_ankle_roll_link" contype="0" conaffinity="0" group="1" density="0" />
                                    <geom size="0.085 0.035 0.004" pos="-0.052 0 -0.043" type="box" rgba="1 1 1 1"/>
                                </body>
                            </body>
                        </body>
                    </body>
                </body>
            </body>
            <body name="base_link" pos="0 0 0.2">
                <inertial pos="-0.00154853 -7.263e-05 -0.0269642" mass="4" diaginertia="0.00957622 0.00654424 0.00526567" />
                <joint name="torso_joint" pos="0 0 0" axis="0 0 1" range="0 0.001" />
                <geom type="mesh" contype="1" conaffinity="1" group="1" density="0" rgba="1 1 1 1" mesh="base_link"/>
                <site name='imu' size='0.01' pos='0.0 0 0.0'/>
                <body name="l_shoulder_pitch_link" pos="0 0.08085 0">
                    <inertial pos="0.00095302 0.058734 -8.0741e-05" mass="0.35" diaginertia="0.00016981 0.00014053 0.00020608" />
                    <joint name="l_shoulder_pitch_joint" pos="0 0 0" axis="0 1 0" range="-3.14 3.14" />
                    <geom type="mesh" mesh="l_shoulder_pitch_link" contype="1" conaffinity="1" group="1" density="0" />
                    <body name="l_shoulder_roll_link" pos="0 0.06515 0">
                        <inertial pos="-0.0088047 8.879e-05 -0.052824" mass="0.35" diaginertia="0.00028497 0.00032147 0.00014121" />
                        <joint name="l_shoulder_roll_joint" pos="0 0 0" axis="1 0 0" range="0 0.001" />
                        <geom type="mesh" mesh="l_shoulder_roll_link" contype="1" conaffinity="1" group="1" density="0" />
                        <body name="l_arm_yaw_link" pos="-0.0026 0 -0.06495">
                            <inertial pos="-0.002422 8.6807e-05 -0.059552" mass="0.35" diaginertia="0.00017393 0.00020583 0.00013651" />
                            <joint name="l_arm_yaw_joint" pos="0 0 0" axis="0 0 1" ref="-1.57" range="0 0.001" />
                            <geom type="mesh" mesh="l_arm_yaw_link" contype="1" conaffinity="1" group="1" density="0" />
                            <body name="l_arm_roll_link" pos="0 0 -0.06645">
                                <inertial pos="0.0088047 -8.879e-05 -0.052824" mass="0.35" diaginertia="0.00028497 0.00032147 0.00014121" />
                                <joint name="l_arm_roll_joint" pos="0 0 0" axis="1 0 0" ref="1.57" range="-3.14 3.14" />
                                <geom type="mesh" mesh="l_arm_roll_link" contype="1" conaffinity="1" group="1" density="0" />
                                <body name="l_wrist_yaw_link" pos="0.0026 0 -0.06495">
                                    <inertial pos="1.1102e-16 3.7151e-14 -0.06558" mass="0.035143" diaginertia="1.2175e-05 1.2175e-05 3.7315e-06" />
                                    <geom type="mesh" mesh="l_wrist_yaw_link" contype="1" conaffinity="1" group="1" density="0" />
                                </body>
                            </body>
                        </body>
                    </body>
                </body>
                <body name="r_shoulder_pitch_link" pos="0 -0.08085 0">
                    <inertial pos="0.00242196 -0.058252 -8.6807e-05" mass="0.35" diaginertia="0.00017393 0.00013651 0.00020583" />
                    <joint name="r_shoulder_pitch_joint" pos="0 0 0" axis="0 1 0" range="-3.14 3.14" />
                    <geom type="mesh" mesh="r_shoulder_pitch_link" contype="1" conaffinity="1" group="1" density="0" />
                    <body name="r_shoulder_roll_link" pos="0 -0.06515 0">
                        <inertial pos="-0.0088047 -8.8789e-05 -0.052824" mass="0.35" diaginertia="0.00028497 0.00032147 0.00014121" />
                        <joint name="r_shoulder_roll_joint" pos="0 0 0" axis="1 0 0" range="0 0.001" />
                        <geom type="mesh" mesh="r_shoulder_roll_link" contype="1" conaffinity="1" group="1" density="0" />
                        <body name="r_arm_yaw_link" pos="-0.0026 0 -0.06495">
                            <inertial pos="-0.002422 -8.6807e-05 -0.059552" mass="0.35" diaginertia="0.00017393 0.00020583 0.00013651" />
                            <joint name="r_arm_yaw_joint" pos="0 0 0" axis="0 0 1" ref="1.57" range="0 0.001" />
                            <geom type="mesh" mesh="r_arm_yaw_link" contype="1" conaffinity="1" group="1" density="0" />
                            <body name="r_arm_roll_link" pos="0 0 -0.06645">
                                <inertial pos="0.0088047 8.8789e-05 -0.052824" mass="0.35" diaginertia="0.00028497 0.00032147 0.00014121" />
                                <joint name="r_arm_roll_joint" pos="0 0 0" axis="1 0 0" ref="-1.57" range="-3.14 3.14" />
                                <geom type="mesh" mesh="r_arm_roll_link" contype="1" conaffinity="1" group="1" density="0" />
                                <body name="r_wrist_yaw_link" pos="0.0026 0 -0.06495">
                                    <inertial pos="0 0 -0.06558" mass="0.035143" diaginertia="1.2175e-05 1.2175e-05 3.7315e-06" />
                                    <geom type="mesh" mesh="r_wrist_yaw_link" contype="1" conaffinity="1" group="1" density="0" />
                                </body>
                            </body>
                        </body>
                    </body>
                </body>
            </body>
        </body>
    </worldbody>
    <actuator>
        <motor name="l_hip_pitch_joint" joint="l_hip_pitch_joint" gear="1" ctrllimited="true" ctrlrange="-32 32" />
        <motor name="l_hip_roll_joint" joint="l_hip_roll_joint" gear="0" ctrllimited="true" ctrlrange="-32 32" />
        <motor name="l_hip_yaw_joint" joint="l_hip_yaw_joint" gear="0" ctrllimited="true" ctrlrange="-32 32" />
        <motor name="l_knee_joint" joint="l_knee_joint" gear="1" ctrllimited="true" ctrlrange="-32 32" />
        <motor name="l_ankle_pitch_joint" joint="l_ankle_pitch_joint" gear="1" ctrllimited="true" ctrlrange="-6 6" />
        <motor name="l_ankle_roll_joint" joint="l_ankle_roll_joint" gear="1" ctrllimited="true" ctrlrange="-6 6" />
        <motor name="r_hip_pitch_joint" joint="r_hip_pitch_joint" gear="1" ctrllimited="true" ctrlrange="-32 32" />
        <motor name="r_hip_roll_joint" joint="r_hip_roll_joint" gear="0" ctrllimited="true" ctrlrange="-32 32" />
        <motor name="r_hip_yaw_joint" joint="r_hip_yaw_joint" gear="0" ctrllimited="true" ctrlrange="-32 32" />
        <motor name="r_knee_joint" joint="r_knee_joint" gear="1" ctrllimited="true" ctrlrange="-32 32" />
        <motor name="r_ankle_pitch_joint" joint="r_ankle_pitch_joint" gear="1" ctrllimited="true" ctrlrange="-6 6" />
        <motor name="r_ankle_roll_joint" joint="r_ankle_roll_joint" gear="1" ctrllimited="true" ctrlrange="-6 6" />
        <motor name="torso_joint" joint="torso_joint" gear="0" ctrllimited="true" ctrlrange="-32 32" />
        <motor name="l_shoulder_pitch_joint" joint="l_shoulder_pitch_joint" gear="1" ctrllimited="true" ctrlrange="-6 6" />
        <motor name="l_shoulder_roll_joint" joint="l_shoulder_roll_joint" gear="0" ctrllimited="true" ctrlrange="-6 6" />
        <motor name="l_arm_yaw_joint" joint="l_arm_yaw_joint" gear="0" ctrllimited="true" ctrlrange="-6 6" />
        <motor name="l_arm_roll_joint" joint="l_arm_roll_joint" gear="1" ctrllimited="true" ctrlrange="-6 6" />
        <motor name="r_shoulder_pitch_joint" joint="r_shoulder_pitch_joint" gear="1" ctrllimited="true" ctrlrange="-6 6" />
        <motor name="r_shoulder_roll_joint" joint="r_shoulder_roll_joint" gear="0" ctrllimited="true" ctrlrange="-6 6" />
        <motor name="r_arm_yaw_joint" joint="r_arm_yaw_joint" gear="0" ctrllimited="true" ctrlrange="-6 6" />
        <motor name="r_arm_roll_joint" joint="r_arm_roll_joint" gear="1" ctrllimited="true" ctrlrange="-6 6" />
    </actuator>
    <sensor>
        <actuatorpos name="l_hip_pitch_joint_p" actuator="l_hip_pitch_joint" user="13" />
        <actuatorvel name="l_hip_pitch_joint_v" actuator="l_hip_pitch_joint" user="13" />
        <actuatorpos name="l_hip_roll_joint_p" actuator="l_hip_roll_joint" user="13" />
        <actuatorvel name="l_hip_roll_joint_v" actuator="l_hip_roll_joint" user="13" />
        <actuatorpos name="l_hip_yaw_joint_p" actuator="l_hip_yaw_joint" user="13" />
        <actuatorvel name="l_hip_yaw_joint_v" actuator="l_hip_yaw_joint" user="13" />
        <actuatorpos name="l_knee_joint_p" actuator="l_knee_joint" user="13" />
        <actuatorvel name="l_knee_joint_v" actuator="l_knee_joint" user="13" />
        <actuatorpos name="l_ankle_pitch_joint_p" actuator="l_ankle_pitch_joint" user="13" />
        <actuatorvel name="l_ankle_pitch_joint_v" actuator="l_ankle_pitch_joint" user="13" />
        <actuatorpos name="l_ankle_roll_joint_p" actuator="l_ankle_roll_joint" user="13" />
        <actuatorvel name="l_ankle_roll_joint_v" actuator="l_ankle_roll_joint" user="13" />
        <actuatorpos name="r_hip_pitch_joint_p" actuator="r_hip_pitch_joint" user="13" />
        <actuatorvel name="r_hip_pitch_joint_v" actuator="r_hip_pitch_joint" user="13" />
        <actuatorpos name="r_hip_roll_joint_p" actuator="r_hip_roll_joint" user="13" />
        <actuatorvel name="r_hip_roll_joint_v" actuator="r_hip_roll_joint" user="13" />
        <actuatorpos name="r_hip_yaw_joint_p" actuator="r_hip_yaw_joint" user="13" />
        <actuatorvel name="r_hip_yaw_joint_v" actuator="r_hip_yaw_joint" user="13" />
        <actuatorpos name="r_knee_joint_p" actuator="r_knee_joint" user="13" />
        <actuatorvel name="r_knee_joint_v" actuator="r_knee_joint" user="13" />
        <actuatorpos name="r_ankle_pitch_joint_p" actuator="r_ankle_pitch_joint" user="13" />
        <actuatorvel name="r_ankle_pitch_joint_v" actuator="r_ankle_pitch_joint" user="13" />
        <actuatorpos name="r_ankle_roll_joint_p" actuator="r_ankle_roll_joint" user="13" />
        <actuatorvel name="r_ankle_roll_joint_v" actuator="r_ankle_roll_joint" user="13" />
        <actuatorpos name="torso_joint_p" actuator="torso_joint" user="13" />
        <actuatorvel name="torso_joint_v" actuator="torso_joint" user="13" />
        <actuatorpos name="l_shoulder_pitch_joint_p" actuator="l_shoulder_pitch_joint" user="13" />
        <actuatorvel name="l_shoulder_pitch_joint_v" actuator="l_shoulder_pitch_joint" user="13" />
        <actuatorpos name="l_shoulder_roll_joint_p" actuator="l_shoulder_roll_joint" user="13" />
        <actuatorvel name="l_shoulder_roll_joint_v" actuator="l_shoulder_roll_joint" user="13" />
        <actuatorpos name="l_arm_yaw_joint_p" actuator="l_arm_yaw_joint" user="13" />
        <actuatorvel name="l_arm_yaw_joint_v" actuator="l_arm_yaw_joint" user="13" />
        <actuatorpos name="l_arm_roll_joint_p" actuator="l_arm_roll_joint" user="13" />
        <actuatorvel name="l_arm_roll_joint_v" actuator="l_arm_roll_joint" user="13" />
        <actuatorpos name="r_shoulder_pitch_joint_p" actuator="r_shoulder_pitch_joint" user="13" />
        <actuatorvel name="r_shoulder_pitch_joint_v" actuator="r_shoulder_pitch_joint" user="13" />
        <actuatorpos name="r_shoulder_roll_joint_p" actuator="r_shoulder_roll_joint" user="13" />
        <actuatorvel name="r_shoulder_roll_joint_v" actuator="r_shoulder_roll_joint" user="13" />
        <actuatorpos name="r_arm_yaw_joint_p" actuator="r_arm_yaw_joint" user="13" />
        <actuatorvel name="r_arm_yaw_joint_v" actuator="r_arm_yaw_joint" user="13" />
        <actuatorpos name="r_arm_roll_joint_p" actuator="r_arm_roll_joint" user="13" />
        <actuatorvel name="r_arm_roll_joint_v" actuator="r_arm_roll_joint" user="13" />

        <framequat     name='orientation' objtype='site' noise='0.001' objname='imu'/>
        <framepos      name='position' objtype='site' noise='0.001' objname='imu'/>
        <gyro          name='angular-velocity'    site='imu' noise='0.005' cutoff='34.9'/>
        <velocimeter   name='linear-velocity'     site='imu' noise='0.001' cutoff='30'/>
        <accelerometer name='linear-acceleration' site='imu' noise='0.005' cutoff='157'/>
        <magnetometer  name='magnetometer'        site='imu'/>
    </sensor>
</mujoco>
